<?xml version="1.0"?>
<!-- 수확 MM: Ridgeback + UR10e + 동축 3축 1/4구 스쿱.
     CAD/Isaac/MoveIt 공통 축: tool0 +Z = 접근·회전축, +Y = 줄기 방향. -->
<robot xmlns:xacro="http://www.ros.org/wiki/xacro" name="harvester_mm">

  <xacro:include filename="$(find ur_description)/urdf/ur_macro.xacro"/>

  <link name="mm_base">
    <visual>
      <origin xyz="0 0 0.15"/>
      <geometry><box size="0.96 0.79 0.30"/></geometry>
      <material name="dark"><color rgba="0.15 0.15 0.15 1"/></material>
    </visual>
    <collision>
      <origin xyz="0 0 0.15"/>
      <geometry><box size="0.96 0.79 0.30"/></geometry>
    </collision>
  </link>

  <xacro:ur_robot
      name="ur"
      tf_prefix=""
      parent="mm_base"
      generate_ros2_control_tag="false"
      joint_limits_parameters_file="$(find ur_description)/config/ur10e/joint_limits.yaml"
      kinematics_parameters_file="$(find ur_description)/config/ur10e/default_kinematics.yaml"
      physical_parameters_file="$(find ur_description)/config/ur10e/physical_parameters.yaml"
      visual_parameters_file="$(find ur_description)/config/ur10e/visual_parameters.yaml">
    <origin xyz="0 0 0.30" rpy="0 0 0"/>
  </xacro:ur_robot>

  <!-- EN ISO 9409-1-50-4-M6 어댑터. 기존 2F-85, 커플러, D455 지그는 사용하지 않는다. -->
  <link name="scoop_adapter">
    <inertial>
      <origin xyz="0 0 0.029"/>
      <mass value="0.85"/>
      <inertia ixx="0.0010" ixy="0" ixz="0" iyy="0.0010" iyz="0" izz="0.0008"/>
    </inertial>
    <visual>
      <geometry><mesh filename="package://harvest_moveit/meshes/coaxial_scoop/UR10eAdapter.stl" scale="0.001 0.001 0.001"/></geometry>
      <material name="adapter_metal"><color rgba="0.42 0.44 0.47 1"/></material>
    </visual>
    <collision>
      <geometry><mesh filename="package://harvest_moveit/meshes/coaxial_scoop/UR10eAdapter.stl" scale="0.001 0.001 0.001"/></geometry>
    </collision>
  </link>
  <joint name="tool0_to_scoop_adapter" type="fixed">
    <parent link="tool0"/>
    <child link="scoop_adapter"/>
    <!-- CAD 닫힘 배치(좌벽+바닥+우벽)가 월드 아래를 향하도록 tool-Z 180° 장착. -->
    <origin xyz="0 0 0" rpy="0 0 3.141592653589793"/>
  </joint>

  <link name="scoop_quarter_1">
    <inertial>
      <origin xyz="0 0 0.120"/>
      <mass value="0.16"/>
      <inertia ixx="0.0005" ixy="0" ixz="0" iyy="0.0005" iyz="0" izz="0.0004"/>
    </inertial>
    <visual>
      <geometry><mesh filename="package://harvest_moveit/meshes/coaxial_scoop/ScoopQuarter1.stl" scale="0.001 0.001 0.001"/></geometry>
      <material name="scoop_inner"><color rgba="0.10 0.52 0.17 1"/></material>
    </visual>
    <collision>
      <geometry><mesh filename="package://harvest_moveit/meshes/coaxial_scoop/ScoopQuarter1.stl" scale="0.001 0.001 0.001"/></geometry>
    </collision>
  </link>
  <joint name="scoop_quarter_1_joint" type="revolute">
    <parent link="scoop_adapter"/>
    <child link="scoop_quarter_1"/>
    <origin xyz="0 0 0" rpy="0 0 0"/>
    <axis xyz="0 0 1"/>
    <limit lower="-1.5707963" upper="1.5707963" effort="40" velocity="1.5"/>
    <dynamics damping="0.8" friction="0.15"/>
  </joint>

  <link name="scoop_quarter_2">
    <inertial>
      <origin xyz="0 0 0.120"/>
      <mass value="0.18"/>
      <inertia ixx="0.0006" ixy="0" ixz="0" iyy="0.0006" iyz="0" izz="0.0005"/>
    </inertial>
    <visual>
      <geometry><mesh filename="package://harvest_moveit/meshes/coaxial_scoop/ScoopQuarter2.stl" scale="0.001 0.001 0.001"/></geometry>
      <material name="scoop_middle"><color rgba="0.08 0.30 0.66 1"/></material>
    </visual>
    <collision>
      <geometry><mesh filename="package://harvest_moveit/meshes/coaxial_scoop/ScoopQuarter2.stl" scale="0.001 0.001 0.001"/></geometry>
    </collision>
  </link>
  <joint name="scoop_quarter_2_joint" type="revolute">
    <parent link="scoop_adapter"/>
    <child link="scoop_quarter_2"/>
    <origin xyz="0 0 0" rpy="0 0 0"/>
    <axis xyz="0 0 1"/>
    <limit lower="-1.5707963" upper="0" effort="40" velocity="1.5"/>
    <dynamics damping="0.8" friction="0.15"/>
  </joint>

  <link name="cutter_quarter_3">
    <inertial>
      <origin xyz="0 0 0.120"/>
      <mass value="0.20"/>
      <inertia ixx="0.0007" ixy="0" ixz="0" iyy="0.0007" iyz="0" izz="0.0006"/>
    </inertial>
    <visual>
      <geometry><mesh filename="package://harvest_moveit/meshes/coaxial_scoop/CutterQuarter3.stl" scale="0.001 0.001 0.001"/></geometry>
      <material name="scoop_cutter"><color rgba="0.82 0.37 0.06 1"/></material>
    </visual>
    <collision>
      <geometry><mesh filename="package://harvest_moveit/meshes/coaxial_scoop/CutterQuarter3.stl" scale="0.001 0.001 0.001"/></geometry>
    </collision>
  </link>
  <joint name="cutter_quarter_3_joint" type="revolute">
    <parent link="scoop_adapter"/>
    <child link="cutter_quarter_3"/>
    <origin xyz="0 0 0" rpy="0 0 0"/>
    <axis xyz="0 0 1"/>
    <limit lower="-3.1415927" upper="0.8726646" effort="50" velocity="1.5"/>
    <dynamics damping="1.0" friction="0.20"/>
  </joint>

  <!-- Eye-in-hand Intel RealSense D455 + L 브래킷.
       Isaac의 실물 USD 외형 envelope(124×29×26mm)와 같은 보수적 박스를 사용한다.
       센서/브래킷은 scoop_adapter의 고정 분기이므로 MoveIt이 월드 충돌을 함께 검사한다. -->
  <link name="harvester_d455_mount">
    <visual>
      <origin xyz="0 0.095 -0.035" rpy="0.550 0 0"/>
      <geometry><box size="0.124 0.029 0.026"/></geometry>
      <material name="d455_black"><color rgba="0.025 0.028 0.032 1"/></material>
    </visual>
    <collision>
      <origin xyz="0 0.095 -0.035" rpy="0.550 0 0"/>
      <!-- 케이블/모서리 3mm 여유를 포함한 충돌 envelope. -->
      <geometry><box size="0.130 0.035 0.032"/></geometry>
    </collision>
    <visual>
      <origin xyz="0 0.064 -0.029"/>
      <geometry><box size="0.090 0.060 0.006"/></geometry>
      <material name="d455_bracket"><color rgba="0.18 0.20 0.23 1"/></material>
    </visual>
    <collision>
      <origin xyz="0 0.064 -0.029"/>
      <geometry><box size="0.090 0.060 0.006"/></geometry>
    </collision>
  </link>
  <joint name="scoop_adapter_to_harvester_d455" type="fixed">
    <parent link="scoop_adapter"/>
    <child link="harvester_d455_mount"/>
    <origin xyz="0 0 0" rpy="0 0 0"/>
  </joint>

  <!-- 토마토 중심. 세 1/4구의 회전 중심과 동일한 tool0 +Z 120 mm. -->
  <link name="harvest_tcp"/>
  <joint name="scoop_adapter_to_harvest_tcp" type="fixed">
    <parent link="scoop_adapter"/>
    <child link="harvest_tcp"/>
    <origin xyz="0 0 0.120" rpy="0 0 0"/>
  </joint>

  <ros2_control name="IsaacTopicBased" type="system">
    <hardware>
      <plugin>topic_based_ros2_control/TopicBasedSystem</plugin>
      <param name="joint_commands_topic">/harvester_moveit/joint_command</param>
      <param name="joint_states_topic">/harvester_moveit/hw_joint_states</param>
    </hardware>
    <joint name="shoulder_pan_joint">
      <command_interface name="position"><param name="initial_value">0.0</param></command_interface>
      <state_interface name="position"><param name="initial_value">0.0</param></state_interface>
      <state_interface name="velocity"/>
    </joint>
    <joint name="shoulder_lift_joint">
      <command_interface name="position"><param name="initial_value">4.7123890</param></command_interface>
      <state_interface name="position"><param name="initial_value">4.7123890</param></state_interface>
      <state_interface name="velocity"/>
    </joint>
    <joint name="elbow_joint">
      <command_interface name="position"><param name="initial_value">1.5707963</param></command_interface>
      <state_interface name="position"><param name="initial_value">1.5707963</param></state_interface>
      <state_interface name="velocity"/>
    </joint>
    <joint name="wrist_1_joint">
      <command_interface name="position"><param name="initial_value">3.1415927</param></command_interface>
      <state_interface name="position"><param name="initial_value">3.1415927</param></state_interface>
      <state_interface name="velocity"/>
    </joint>
    <joint name="wrist_2_joint">
      <command_interface name="position"><param name="initial_value">-1.5707963</param></command_interface>
      <state_interface name="position"><param name="initial_value">-1.5707963</param></state_interface>
      <state_interface name="velocity"/>
    </joint>
    <joint name="wrist_3_joint">
      <command_interface name="position"><param name="initial_value">0.0</param></command_interface>
      <state_interface name="position"><param name="initial_value">0.0</param></state_interface>
      <state_interface name="velocity"/>
    </joint>
    <joint name="scoop_quarter_1_joint">
      <command_interface name="position"><param name="initial_value">0.0</param></command_interface>
      <state_interface name="position"><param name="initial_value">0.0</param></state_interface>
      <state_interface name="velocity"/>
    </joint>
    <joint name="scoop_quarter_2_joint">
      <command_interface name="position"><param name="initial_value">-1.5707963</param></command_interface>
      <state_interface name="position"><param name="initial_value">-1.5707963</param></state_interface>
      <state_interface name="velocity"/>
    </joint>
    <joint name="cutter_quarter_3_joint">
      <command_interface name="position"><param name="initial_value">-3.1415927</param></command_interface>
      <state_interface name="position"><param name="initial_value">-3.1415927</param></state_interface>
      <state_interface name="velocity"/>
    </joint>
  </ros2_control>

</robot>
